Workbook

Sheet WA_Fn-UseC_-Telco-Customer-Chur
A1: customerID | B1: gender | C1: SeniorCitizen | D1: Partner | E1: Dependents | F1: tenure | G1: TenureGroup | H1: PhoneService | I1: MultipleLines | J1: InternetService | K1: OnlineSecurity | L1: OnlineBackup | M1: DeviceProtection | N1: TechSupport | O1: StreamingTV | P1: StreamingMovies | Q1: Contract | R1: PaperlessBilling | S1: PaymentMethod | T1: MonthlyCharges | U1: TotalCharges | V1: ChurnFlag | W1: Churn
A2: 7590-VHVEG | B2: Female | C2: 0 | D2: Yes | E2: No | F2: 1 | G2: =IF(Telco[[#This Row],[tenure]]<=12,"0–12",IF(Telco[[#This Row],[tenure]]<=24,"13–24",IF(Telco[[#This Row],[tenure]]<=48,"25–48","49–72"))) -> 0–12 | H2: No | I2: No phone service | J2: DSL | K2: No | L2: Yes | M2: No | N2: No | O2: No | P2: No | Q2: Month-to-month | R2: Yes | S2: Electronic check | T2: 29.85 | U2: 29.85 | V2: =IF(Telco[[#This Row],[Churn]]="Yes",1,0) -> 0 | W2: No
A3: 5575-GNVDE | B3: Male | C3: 0 | D3: No | E3: No | F3: 34 | G3: =IF(Telco[[#This Row],[tenure]]<=12,"0–12",IF(Telco[[#This Row],[tenure]]<=24,"13–24",IF(Telco[[#This Row],[tenure]]<=48,"25–48","49–72"))) -> 25–48 | H3: Yes | I3: No | J3: DSL | K3: Yes | L3: No | M3: Yes | N3: No | O3: No | P3: No | Q3: One year | R3: No | S3: Mailed check | T3: 56.95 | U3: 1889.5 | V3: =IF(Telco[[#This Row],[Churn]]="Yes",1,0) -> 0 | W3: No
A4: 3668-QPYBK | B4: Male | C4: 0 | D4: No | E4: No | F4: 2 | G4: =IF(Telco[[#This Row],[tenure]]<=12,"0–12",IF(Telco[[#This Row],[tenure]]<=24,"13–24",IF(Telco[[#This Row],[tenure]]<=48,"25–48","49–72"))) -> 0–12 | H4: Yes | I4: No | J4: DSL | K4: Yes | L4: Yes | M4: No | N4: No | O4: No | P4: No | Q4: Month-to-month | R4: Yes | S4: Mailed check | T4: 53.85 | U4: 108.15 | V4: =IF(Telco[[#This Row],[Churn]]="Yes",1,0) -> 1 | W4: Yes
A5: 7795-CFOCW | B5: Male | C5: 0 | D5: No | E5: No | F5: 45 | G5: =IF(Telco[[#This Row],[tenure]]<=12,"0–12",IF(Telco[[#This Row],[tenure]]<=24,"13–24",IF(Telco[[#This Row],[tenure]]<=48,"25–48","49–72"))) -> 25–48 | H5: No | I5: No phone service | J5: DSL | K5: Yes | L5: No | M5: Yes | N5: Yes | O5: No | P5: No | Q5: One year | R5: No | S5: Bank transfer (automatic) | T5: 42.3 | U5: 1840.75 | V5: =IF(Telco[[#This Row],[Churn]]="Yes",1,0) -> 0 | W5: No
A6: 9237-HQITU | B6: Female | C6: 0 | D6: No | E6: No | F6: 2 | G6: =IF(Telco[[#This Row],[tenure]]<=12,"0–12",IF(Telco[[#This Row],[tenure]]<=24,"13–24",IF(Telco[[#This Row],[tenure]]<=48,"25–48","49–72"))) -> 0–12 | H6: Yes | I6: No | J6: Fiber optic | K6: No | L6: No | M6: No | N6: No | O6: No | P6: No | Q6: Month-to-month | R6: Yes | S6: Electronic check | T6: 70.7 | U6: 151.65 | V6: =IF(Telco[[#This Row],[Churn]]="Yes",1,0) -> 1 | W6: Yes
A7: 9305-CDSKC | B7: Female | C7: 0 | D7: No | E7: No | F7: 8 | G7: =IF(Telco[[#This Row],[tenure]]<=12,"0–12",IF(Telco[[#This Row],[tenure]]<=24,"13–24",IF(Telco[[#This Row],[tenure]]<=48,"25–48","49–72"))) -> 0–12 | H7: Yes | I7: Yes | J7: Fiber optic | K7: No | L7: No | M7: Yes | N7: No | O7: Yes | P7: Yes | Q7: Month-to-month | R7: Yes | S7: Electronic check | T7: 99.65 | U7: 820.5 | V7: =IF(Telco[[#This Row],[Churn]]="Yes",1,0) -> 1 | W7: Yes
A8: 1452-KIOVK | B8: Male | C8: 0 | D8: No | E8: Yes | F8: 22 | G8: =IF(Telco[[#This Row],[tenure]]<=12,"0–12",IF(Telco[[#This Row],[tenure]]<=24,"13–24",IF(Telco[[#This Row],[tenure]]<=48,"25–48","49–72"))) -> 13–24 | H8: Yes | I8: Yes | J8: Fiber optic | K8: No | L8: Yes | M8: No | N8: No | O8: Yes | P8: No | Q8: Month-to-month | R8: Yes | S8: Credit card (automatic) | T8: 89.1 | U8: 1949.4 | V8: =IF(Telco[[#This Row],[Churn]]="Yes",1,0) -> 0 | W8: No
A9: 6713-OKOMC | B9: Female | C9: 0 | D9: No | E9: No | F9: 10 | G9: =IF(Telco[[#This Row],[tenure]]<=12,"0–12",IF(Telco[[#This Row],[tenure]]<=24,"13–24",IF(Telco[[#This Row],[tenure]]<=48,"25–48","49–72"))) -> 0–12 | H9: No | I9: No phone service | J9: DSL | K9: Yes | L9: No | M9: No | N9: No | O9: No | P9: No | Q9: Month-to-month | R9: No | S9: Mailed check | T9: 29.75 | U9: 301.9 | V9: =IF(Telco[[#This Row],[Churn]]="Yes",1,0) -> 0 | W9: No
A10: 7892-POOKP | B10: Female | C10: 0 | D10: Yes | E10: No | F10: 28 | G10: =IF(Telco[[#This Row],[tenure]]<=12,"0–12",IF(Telco[[#This Row],[tenure]]<=24,"13–24",IF(Telco[[#This Row],[tenure]]<=48,"25–48","49–72"))) -> 25–48 | H10: Yes | I10: Yes | J10: Fiber optic | K10: No | L10: No | M10: Yes | N10: Yes | O10: Yes | P10: Yes | Q10: Month-to-month | R10: Yes | S10: Electronic check | T10: 104.8 | U10: 3046.05 | V10: =IF(Telco[[#This Row],[Churn]]="Yes",1,0) -> 1 | W10: Yes
A11: 6388-TABGU | B11: Male | C11: 0 | D11: No | E11: Yes | F11: 62 | G11: =IF(Telco[[#This Row],[tenure]]<=12,"0–12",IF(Telco[[#This Row],[tenure]]<=24,"13–24",IF(Telco[[#This Row],[tenure]]<=48,"25–48","49–72"))) -> 49–72 | H11: Yes | I11: No | J11: DSL | K11: Yes | L11: Yes | M11: No | N11: No | O11: No | P11: No | Q11: One year | R11: No | S11: Bank transfer (automatic) | T11: 56.15 | U11: 3487.95 | V11: =IF(Telco[[#This Row],[Churn]]="Yes",1,0) -> 0 | W11: No
A12: 9763-GRSKD | B12: Male | C12: 0 | D12: Yes | E12: Yes | F12: 13 | G12: =IF(Telco[[#This Row],[tenure]]<=12,"0–12",IF(Telco[[#This Row],[tenure]]<=24,"13–24",IF(Telco[[#This Row],[tenure]]<=48,"25–48","49–72"))) -> 13–24 | H12: Yes | I12: No | J12: DSL | K12: Yes | L12: No | M12: No | N12: No | O12: No | P12: No | Q12: Month-to-month | R12: Yes | S12: Mailed check | T12: 49.95 | U12: 587.45 | V12: =IF(Telco[[#This Row],[Churn]]="Yes",1,0) -> 0 | W12: No
A13: 7469-LKBCI | B13: Male | C13: 0 | D13: No | E13: No | F13: 16 | G13: =IF(Telco[[#This Row],[tenure]]<=12,"0–12",IF(Telco[[#This Row],[tenure]]<=24,"13–24",IF(Telco[[#This Row],[tenure]]<=48,"25–48","49–72"))) -> 13–24 | H13: Yes | I13: No | J13: No | K13: No internet service | L13: No internet service | M13: No internet service | N13: No internet service | O13: No internet service | P13: No internet service | Q13: Two year | R13: No | S13: Credit card (automatic) | T13: 18.95 | U13: 326.8 | V13: =IF(Telco[[#This Row],[Churn]]="Yes",1,0) -> 0 | W13: No
... A489: 3649-JPUGY | B489: Male | C489: 0 | D489: No | E489: No | F489: 72 | G489: =IF(Telco[[#This Row],[tenure]]<=12,"0–12",IF(Telco[[#This Row],[tenure]]<=24,"13–24",IF(Telco[[#This Row],[tenure]]<=48,"25–48","49–72"))) -> 49–72 | H489: Yes | I489: Yes | J489: DSL | K489: No | L489: Yes | M489: Yes | N489: Yes | O489: Yes | P489: Yes | Q489: Two year | R489: Yes | S489: Bank transfer (automatic) | T489: 88.6 | U489: 6201.95 | V489: =IF(Telco[[#This Row],[Churn]]="Yes",1,0) -> 0 | W489: No
A490: 4472-LVYGI | B490: Female | C490: 0 | D490: Yes | E490: Yes | F490: 0 | G490: =IF(Telco[[#This Row],[tenure]]<=12,"0–12",IF(Telco[[#This Row],[tenure]]<=24,"13–24",IF(Telco[[#This Row],[tenure]]<=48,"25–48","49–72"))) -> 0–12 | H490: No | I490: No phone service | J490: DSL | K490: Yes | L490: No | M490: Yes | N490: Yes | O490: Yes | P490: No | Q490: Two year | R490: Yes | S490: Bank transfer (automatic) | T490: 52.55 | V490: =IF(Telco[[#This Row],[Churn]]="Yes",1,0) -> 0 | W490: No
A491: 8372-JUXUI | B491: Male | C491: 0 | D491: No | E491: Yes | F491: 1 | G491: =IF(Telco[[#This Row],[tenure]]<=12,"0–12",IF(Telco[[#This Row],[tenure]]<=24,"13–24",IF(Telco[[#This Row],[tenure]]<=48,"25–48","49–72"))) -> 0–12 | H491: Yes | I491: Yes | J491: Fiber optic | K491: No | L491: No | M491: No | N491: No | O491: No | P491: No | Q491: Month-to-month | R491: Yes | S491: Electronic check | T491: 74.35 | U491: 74.35 | V491: =IF(Telco[[#This Row],[Churn]]="Yes",1,0) -> 1 | W491: Yes
A492: 3552-CTCYF | B492: Male | C492: 0 | D492: Yes | E492: Yes | F492: 63 | G492: =IF(Telco[[#This Row],[tenure]]<=12,"0–12",IF(Telco[[#This Row],[tenure]]<=24,"13–24",IF(Telco[[#This Row],[tenure]]<=48,"25–48","49–72"))) -> 49–72 | H492: Yes | I492: Yes | J492: Fiber optic | K492: No | L492: Yes | M492: Yes | N492: No | O492: Yes | P492: Yes | Q492: Two year | R492: Yes | S492: Bank transfer (automatic) | T492: 104.8 | U492: 6597.25 | V492: =IF(Telco[[#This Row],[Churn]]="Yes",1,0) -> 0 | W492: No
A493: 6778-YSNIH | B493: Female | C493: 0 | D493: No | E493: No | F493: 2 | G493: =IF(Telco[[#This Row],[tenure]]<=12,"0–12",IF(Telco[[#This Row],[tenure]]<=24,"13–24",IF(Telco[[#This Row],[tenure]]<=48,"25–48","49–72"))) -> 0–12 | H493: Yes | I493: No | J493: DSL | K493: No | L493: Yes | M493: No | N493: No | O493: Yes | P493: No | Q493: Month-to-month | R493: Yes | S493: Electronic check | T493: 59 | U493: 114.15 | V493: =IF(Telco[[#This Row],[Churn]]="Yes",1,0) -> 0 | W493: No
A494: 0388-EOPEX | B494: Female | C494: 0 | D494: Yes | E494: No | F494: 2 | G494: =IF(Telco[[#This Row],[tenure]]<=12,"0–12",IF(Telco[[#This Row],[tenure]]<=24,"13–24",IF(Telco[[#This Row],[tenure]]<=48,"25–48","49–72"))) -> 0–12 | H494: Yes | I494: No | J494: Fiber optic | K494: Yes | L494: No | M494: No | N494: No | O494: No | P494: No | Q494: Month-to-month | R494: Yes | S494: Electronic check | T494: 74.4 | U494: 139.4 | V494: =IF(Telco[[#This Row],[Churn]]="Yes",1,0) -> 1 | W494: Yes
A495: 5756-OZRIO | B495: Male | C495: 1 | D495: Yes | E495: No | F495: 61 | G495: =IF(Telco[[#This Row],[tenure]]<=12,"0–12",IF(Telco[[#This Row],[tenure]]<=24,"13–24",IF(Telco[[#This Row],[tenure]]<=48,"25–48","49–72"))) -> 49–72 | H495: Yes | I495: Yes | J495: DSL | K495: No | L495: Yes | M495: No | N495: No | O495: No | P495: Yes | Q495: One year | R495: No | S495: Bank transfer (automatic) | T495: 64.05 | U495: 3902.6 | V495: =IF(Telco[[#This Row],[Churn]]="Yes",1,0) -> 0 | W495: No
A496: 6579-JPICP | B496: Male | C496: 0 | D496: No | E496: No | F496: 1 | G496: =IF(Telco[[#This Row],[tenure]]<=12,"0–12",IF(Telco[[#This Row],[tenure]]<=24,"13–24",IF(Telco[[#This Row],[tenure]]<=48,"25–48","49–72"))) -> 0–12 | H496: Yes | I496: No | J496: No | K496: No internet service | L496: No internet service | M496: No internet service | N496: No internet service | O496: No internet service | P496: No internet service | Q496: Month-to-month | R496: No | S496: Mailed check | T496: 20.4 | U496: 20.4 | V496: =IF(Telco[[#This Row],[Churn]]="Yes",1,0) -> 0 | W496: No
A497: 8205-OTCHB | B497: Male | C497: 0 | D497: No | E497: No | F497: 22 | G497: =IF(Telco[[#This Row],[tenure]]<=12,"0–12",IF(Telco[[#This Row],[tenure]]<=24,"13–24",IF(Telco[[#This Row],[tenure]]<=48,"25–48","49–72"))) -> 13–24 | H497: No | I497: No phone service | J497: DSL | K497: No | L497: Yes | M497: Yes | N497: No | O497: No | P497: Yes | Q497: One year | R497: Yes | S497: Bank transfer (automatic) | T497: 43.75 | U497: 903.6 | V497: =IF(Telco[[#This Row],[Churn]]="Yes",1,0) -> 1 | W497: Yes
A498: 4134-BSXLX | B498: Male | C498: 0 | D498: Yes | E498: No | F498: 28 | G498: =IF(Telco[[#This Row],[tenure]]<=12,"0–12",IF(Telco[[#This Row],[tenure]]<=24,"13–24",IF(Telco[[#This Row],[tenure]]<=48,"25–48","49–72"))) -> 25–48 | H498: Yes | I498: No | J498: DSL | K498: Yes | L498: Yes | M498: No | N498: Yes | O498: No | P498: No | Q498: Month-to-month | R498: No | S498: Mailed check | T498: 60.9 | U498: 1785.65 | V498: =IF(Telco[[#This Row],[Churn]]="Yes",1,0) -> 0 | W498: No
A499: 0505-SPOOW | B499: Female | C499: 0 | D499: Yes | E499: No | F499: 70 | G499: =IF(Telco[[#This Row],[tenure]]<=12,"0–12",IF(Telco[[#This Row],[tenure]]<=24,"13–24",IF(Telco[[#This Row],[tenure]]<=48,"25–48","49–72"))) -> 49–72 | H499: Yes | I499: No | J499: No | K499: No internet service | L499: No internet service | M499: No internet service | N499: No internet service | O499: No internet service | P499: No internet service | Q499: Two year | R499: No | S499: Bank transfer (automatic) | T499: 19.8 | U499: 1397.65 | V499: =IF(Telco[[#This Row],[Churn]]="Yes",1,0) -> 0 | W499: No
A500: 6235-VDHOM | B500: Female | C500: 1 | D500: No | E500: No | F500: 5 | G500: =IF(Telco[[#This Row],[tenure]]<=12,"0–12",IF(Telco[[#This Row],[tenure]]<=24,"13–24",IF(Telco[[#This Row],[tenure]]<=48,"25–48","49–72"))) -> 0–12 | H500: No | I500: No phone service | J500: DSL | K500: No | L500: Yes | M500: No | N500: No | O500: No | P500: No | Q500: Month-to-month | R500: No | S500: Electronic check | T500: 28.45 | U500: 131.05 | V500: =IF(Telco[[#This Row],[Churn]]="Yes",1,0) -> 1 | W500: Yes
A501: 7783-YKGDV | B501: Female | C501: 0 | D501: No | E501: No | F501: 12 | G501: =IF(Telco[[#This Row],[tenure]]<=12,"0–12",IF(Telco[[#This Row],[tenure]]<=24,"13–24",IF(Telco[[#This Row],[tenure]]<=48,"25–48","49–72"))) -> 0–12 | H501: Yes | I501: Yes | J501: Fiber optic | K501: Yes | L501: Yes | M501: Yes | N501: No | O501: No | P501: Yes | Q501: Month-to-month | R501: Yes | S501: Bank transfer (automatic) | T501: 99.7 | U501: 1238.45 | V501: =IF(Telco[[#This Row],[Churn]]="Yes",1,0) -> 1 | W501: Yes
A502: 4374-YMUSQ | B502: Male | C502: 0 | D502: No | E502: No | F502: 34 | G502: =IF(Telco[[#This Row],[tenure]]<=12,"0–12",IF(Telco[[#This Row],[tenure]]<=24,"13–24",IF(Telco[[#This Row],[tenure]]<=48,"25–48","49–72"))) -> 25–48 | H502: Yes | I502: Yes | J502: Fiber optic | K502: Yes | L502: Yes | M502: Yes | N502: Yes | O502: Yes | P502: Yes | Q502: One year | R502: No | S502: Credit card (automatic) | T502: 116.25 | U502: 3899.05 | V502: =IF(Telco[[#This Row],[Churn]]="Yes",1,0) -> 0 | W502: No
... A754: 1410-RSCMR | B754: Male | C754: 0 | D754: Yes | E754: Yes | F754: 7 | G754: =IF(Telco[[#This Row],[tenure]]<=12,"0–12",IF(Telco[[#This Row],[tenure]]<=24,"13–24",IF(Telco[[#This Row],[tenure]]<=48,"25–48","49–72"))) -> 0–12 | H754: Yes | I754: No | J754: DSL | K754: Yes | L754: No | M754: Yes | N754: Yes | O754: No | P754: Yes | Q754: Month-to-month | R754: Yes | S754: Credit card (automatic) | T754: 71.35 | U754: 515.75 | V754: =IF(Telco[[#This Row],[Churn]]="Yes",1,0) -> 0 | W754: No
A755: 3115-CZMZD | B755: Male | C755: 0 | D755: No | E755: Yes | F755: 0 | G755: =IF(Telco[[#This Row],[tenure]]<=12,"0–12",IF(Telco[[#This Row],[tenure]]<=24,"13–24",IF(Telco[[#This Row],[tenure]]<=48,"25–48","49–72"))) -> 0–12 | H755: Yes | I755: No | J755: No | K755: No internet service | L755: No internet service | M755: No internet service | N755: No internet service | O755: No internet service | P755: No internet service | Q755: Two year | R755: No | S755: Mailed check | T755: 20.25 | V755: =IF(Telco[[#This Row],[Churn]]="Yes",1,0) -> 0 | W755: No
A756: 0139-IVFJG | B756: Female | C756: 0 | D756: Yes | E756: No | F756: 2 | G756: =IF(Telco[[#This Row],[tenure]]<=12,"0–12",IF(Telco[[#This Row],[tenure]]<=24,"13–24",IF(Telco[[#This Row],[tenure]]<=48,"25–48","49–72"))) -> 0–12 | H756: Yes | I756: No | J756: Fiber optic | K756: Yes | L756: Yes | M756: No | N756: No | O756: Yes | P756: No | Q756: Month-to-month | R756: No | S756: Electronic check | T756: 90.35 | U756: 190.5 | V756: =IF(Telco[[#This Row],[Churn]]="Yes",1,0) -> 0 | W756: No
A757: 6683-VLCTZ | B757: Male | C757: 1 | D757: No | E757: No | F757: 20 | G757: =IF(Telco[[#This Row],[tenure]]<=12,"0–12",IF(Telco[[#This Row],[tenure]]<=24,"13–24",IF(Telco[[#This Row],[tenure]]<=48,"25–48","49–72"))) -> 13–24 | H757: Yes | I757: Yes | J757: Fiber optic | K757: No | L757: No | M757: Yes | N757: No | O757: Yes | P757: Yes | Q757: Month-to-month | R757: Yes | S757: Electronic check | T757: 98.55 | U757: 1842.8 | V757: =IF(Telco[[#This Row],[Churn]]="Yes",1,0) -> 1 | W757: Yes
A758: 5730-DBDSI | B758: Male | C758: 0 | D758: No | E758: No | F758: 66 | G758: =IF(Telco[[#This Row],[tenure]]<=12,"0–12",IF(Telco[[#This Row],[tenure]]<=24,"13–24",IF(Telco[[#This Row],[tenure]]<=48,"25–48","49–72"))) -> 49–72 | H758: Yes | I758: No | J758: No | K758: No internet service | L758: No internet service | M758: No internet service | N758: No internet service | O758: No internet service | P758: No internet service | Q758: Two year | R758: No | S758: Bank transfer (automatic) | T758: 19.7 | U758: 1253.8 | V758: =IF(Telco[[#This Row],[Churn]]="Yes",1,0) -> 0 | W758: No
A759: 0030-FNXPP | B759: Female | C759: 0 | D759: No | E759: No | F759: 3 | G759: =IF(Telco[[#This Row],[tenure]]<=12,"0–12",IF(Telco[[#This Row],[tenure]]<=24,"13–24",IF(Telco[[#This Row],[tenure]]<=48,"25–48","49–72"))) -> 0–12 | H759: Yes | I759: No | J759: No | K759: No internet service | L759: No internet service | M759: No internet service | N759: No internet service | O759: No internet service | P759: No internet service | Q759: Month-to-month | R759: No | S759: Mailed check | T759: 19.85 | U759: 57.2 | V759: =IF(Telco[[#This Row],[Churn]]="Yes",1,0) -> 0 | W759: No
A760: 2189-WWOEW | B760: Female | C760: 0 | D760: No | E760: Yes | F760: 15 | G760: =IF(Telco[[#This Row],[tenure]]<=12,"0–12",IF(Telco[[#This Row],[tenure]]<=24,"13–24",IF(Telco[[#This Row],[tenure]]<=48,"25–48","49–72"))) -> 13–24 | H760: Yes | I760: No | J760: Fiber optic | K760: No | L760: Yes | M760: No | N760: No | O760: No | P760: Yes | Q760: Month-to-month | R760: Yes | S760: Bank transfer (automatic) | T760: 85.9 | U760: 1269.55 | V760: =IF(Telco[[#This Row],[Churn]]="Yes",1,0) -> 1 | W760: Yes
A761: 5684-FJVYR | B761: Female | C761: 0 | D761: Yes | E761: Yes | F761: 72 | G761: =IF(Telco[[#This Row],[tenure]]<=12,"0–12",IF(Telco[[#This Row],[tenure]]<=24,"13–24",IF(Telco[[#This Row],[tenure]]<=48,"25–48","49–72"))) -> 49–72 | H761: Yes | I761: Yes | J761: Fiber optic | K761: Yes | L761: Yes | M761: No | N761: Yes | O761: No | P761: No | Q761: Two year | R761: Yes | S761: Bank transfer (automatic) | T761: 90.35 | U761: 6563.4 | V761: =IF(Telco[[#This Row],[Churn]]="Yes",1,0) -> 0 | W761: No
A762: 4013-GUXND | B762: Male | C762: 0 | D762: No | E762: No | F762: 1 | G762: =IF(Telco[[#This Row],[tenure]]<=12,"0–12",IF(Telco[[#This Row],[tenure]]<=24,"13–24",IF(Telco[[#This Row],[tenure]]<=48,"25–48","49–72"))) -> 0–12 | H762: Yes | I762: No | J762: No | K762: No internet service | L762: No internet service | M762: No internet service | N762: No internet service | O762: No internet service | P762: No internet service | Q762: Month-to-month | R762: No | S762: Mailed check | T762: 20.8 | U762: 20.8 | V762: =IF(Telco[[#This Row],[Churn]]="Yes",1,0) -> 0 | W762: No
A763: 1894-IGFSG | B763: Female | C763: 0 | D763: No | E763: No | F763: 22 | G763: =IF(Telco[[#This Row],[tenure]]<=12,"0–12",IF(Telco[[#This Row],[tenure]]<=24,"13–24",IF(Telco[[#This Row],[tenure]]<=48,"25–48","49–72"))) -> 13–24 | H763: Yes | I763: No | J763: Fiber optic | K763: No | L763: No | M763: No | N763: No | O763: Yes | P763: Yes | Q763: Month-to-month | R763: No | S763: Electronic check | T763: 89.25 | U763: 1907.85 | V763: =IF(Telco[[#This Row],[Churn]]="Yes",1,0) -> 1 | W763: Yes
A764: 7379-POKDZ | B764: Male | C764: 0 | D764: Yes | E764: No | F764: 3 | G764: =IF(Telco[[#This Row],[tenure]]<=12,"0–12",IF(Telco[[#This Row],[tenure]]<=24,"13–24",IF(Telco[[#This Row],[tenure]]<=48,"25–48","49–72"))) -> 0–12 | H764: Yes | I764: No | J764: Fiber optic | K764: No | L764: No | M764: No | N764: No | O764: No | P764: No | Q764: Month-to-month | R764: Yes | S764: Electronic check | T764: 70.3 | U764: 208.85 | V764: =IF(Telco[[#This Row],[Churn]]="Yes",1,0) -> 1 | W764: Yes
A765: 1266-NZYUI | B765: Female | C765: 0 | D765: Yes | E765: Yes | F765: 72 | G765: =IF(Telco[[#This Row],[tenure]]<=12,"0–12",IF(Telco[[#This Row],[tenure]]<=24,"13–24",IF(Telco[[#This Row],[tenure]]<=48,"25–48","49–72"))) -> 49–72 | H765: Yes | I765: Yes | J765: DSL | K765: Yes | L765: No | M765: Yes | N765: Yes | O765: No | P765: No | Q765: Two year | R765: No | S765: Bank transfer (automatic) | T765: 66.85 | U765: 4758.8 | V765: =IF(Telco[[#This Row],[Churn]]="Yes",1,0) -> 0 | W765: No
A766: 7969-FFOWG | B766: Male | C766: 0 | D766: Yes | E766: Yes | F766: 65 | G766: =IF(Telco[[#This Row],[tenure]]<=12,"0–12",IF(Telco[[#This Row],[tenure]]<=24,"13–24",IF(Telco[[#This Row],[tenure]]<=48,"25–48","49–72"))) -> 49–72 | H766: Yes | I766: No | J766: No | K766: No internet service | L766: No internet service | M766: No internet service | N766: No internet service | O766: No internet service | P766: No internet service | Q766: Two year | R766: No | S766: Mailed check | T766: 19.9 | U766: 1292.6 | V766: =IF(Telco[[#This Row],[Churn]]="Yes",1,0) -> 0 | W766: No
...

Sheet feuille KPI
A1: kpi | B1: nombre | C1: pourcentage | F1: Contract | G1: OnlineSecurity | H1: TechSupport | I1: ChurnFlag | J1: PaymentMethod | K1: customerID
A2: Taux de désabonnement | B2: =SUM(Telco[ChurnFlag])/COUNTA(Telco[customerID]) -> 0.26536987 | F2: Month-to-month | G2: No | H2: No | I2: =IF(Telco[[#This Row],[Churn]]="Yes",1,0) -> 0 | J2: Electronic check | K2: 7590-VHVEG
A3: Répartition du genre | F3: One year | G3: Yes | H3: No | I3: =IF(Telco[[#This Row],[Churn]]="Yes",1,0) -> 0 | J3: Mailed check | K3: 5575-GNVDE
A4: male | B4: =COUNTIF(Telco[gender],"Male") -> 3555 | C4: =COUNTIF(Telco[gender],"Male")/COUNTA(Telco[gender]) -> 0.5047565 | F4: Month-to-month | G4: Yes | H4: No | I4: =IF(Telco[[#This Row],[Churn]]="Yes",1,0) -> 1 | J4: Mailed check | K4: 3668-QPYBK
A5: femelle | B5: =COUNTIF(Telco[gender],"Female") -> 3488 | C5: =COUNTIF(Telco[gender],"Female")/COUNTA(Telco[gender]) -> 0.4952435 | F5: One year | G5: Yes | H5: Yes | I5: =IF(Telco[[#This Row],[Churn]]="Yes",1,0) -> 0 | J5: Bank transfer (automatic) | K5: 7795-CFOCW
F6: Month-to-month | G6: No | H6: No | I6: =IF(Telco[[#This Row],[Churn]]="Yes",1,0) -> 1 | J6: Electronic check | K6: 9237-HQITU | N6: Méthodes de paiement
F7: Month-to-month | G7: No | H7: No | I7: =IF(Telco[[#This Row],[Churn]]="Yes",1,0) -> 1 | J7: Electronic check | K7: 9305-CDSKC
A8: % de clients âgés : | C8: =COUNTIF(Telco[SeniorCitizen],1)/COUNTA(Telco[SeniorCitizen]) -> 0.16214681 | F8: Month-to-month | G8: No | H8: No | I8: =IF(Telco[[#This Row],[Churn]]="Yes",1,0) -> 0 | J8: Credit card (automatic) | K8: 1452-KIOVK | N8: Étiquettes de lignes | O8: Nombre de customerID
A9: % non âgés : | C9: =COUNTIF(Telco[SeniorCitizen],0)/COUNTA(Telco[SeniorCitizen]) -> 0.83785319 | F9: Month-to-month | G9: Yes | H9: No | I9: =IF(Telco[[#This Row],[Churn]]="Yes",1,0) -> 0 | J9: Mailed check | K9: 6713-OKOMC | N9: Bank transfer (automatic) | O9: 0.21922476
A10: % avec partenaire | C10: =COUNTIF(Telco[Partner],"Yes")/COUNTA(Telco[Partner]) -> 0.4830328 | F10: Month-to-month | G10: No | H10: Yes | I10: =IF(Telco[[#This Row],[Churn]]="Yes",1,0) -> 1 | J10: Electronic check | K10: 7892-POOKP | N10: Credit card (automatic) | O10: 0.21610109
A11: % avec personnes à charge : | C11: =COUNTIF(Telco[Dependents],"Yes")/COUNTA(Telco[Dependents]) -> 0.29958824 | F11: One year | G11: Yes | H11: No | I11: =IF(Telco[[#This Row],[Churn]]="Yes",1,0) -> 0 | J11: Bank transfer (automatic) | K11: 6388-TABGU | N11: Electronic check | O11: 0.33579441
A12: % avec Internet : | C12: =(COUNTIF(Telco[InternetService],"DSL")+COUNTIF(Telco[InternetService],"Fiber optic"))/COUNTA(Telco[InternetService]) -> 0.78333097 | F12: Month-to-month | G12: Yes | H12: No | I12: =IF(Telco[[#This Row],[Churn]]="Yes",1,0) -> 0 | J12: Mailed check | K12: 9763-GRSKD | N12: Mailed check | O12: 0.22887974
A13: % avec Online Security : | C13: =COUNTIF(Telco[OnlineSecurity],"Yes")/COUNTA(Telco[OnlineSecurity]) -> 0.28666761 | F13: Two year | G13: No internet service | H13: No internet service | I13: =IF(Telco[[#This Row],[Churn]]="Yes",1,0) -> 0 | J13: Credit card (automatic) | K13: 7469-LKBCI | N13: (vide) | O13: 0
A14: % avec Online Backup | C14: =COUNTIF(Telco[OnlineBackup],"Yes")/COUNTA(Telco[OnlineBackup]) -> 0.34488144 | F14: One year | G14: No | H14: No | I14: =IF(Telco[[#This Row],[Churn]]="Yes",1,0) -> 0 | J14: Credit card (automatic) | K14: 8091-TTVAX | N14: Total général | O14: 1
A15: % avec Device Protection : | C15: =COUNTIF(Telco[DeviceProtection],"Yes")/COUNTA(Telco[DeviceProtection]) -> 0.34388755 | F15: Month-to-month | G15: No | H15: No | I15: =IF(Telco[[#This Row],[Churn]]="Yes",1,0) -> 1 | J15: Bank transfer (automatic) | K15: 0280-XJGEX
A16: % avec Tech Support | C16: =COUNTIF(Telco[TechSupport],"Yes")/COUNTA(Telco[TechSupport]) -> 0.29021724 | F16: Month-to-month | G16: Yes | H16: Yes | I16: =IF(Telco[[#This Row],[Churn]]="Yes",1,0) -> 0 | J16: Electronic check | K16: 5129-JLPIS
A17: % avec StreamingTV | C17: =COUNTIF(Telco[StreamingTV],"Yes")/COUNTA(Telco[StreamingTV]) -> 0.38435326 | F17: Two year | G17: Yes | H17: Yes | I17: =IF(Telco[[#This Row],[Churn]]="Yes",1,0) -> 0 | J17: Credit card (automatic) | K17: 3655-SNQYZ
A18: % avec StreamingMovies | C18: =COUNTIF(Telco[StreamingMovies],"Yes")/COUNTA(Telco[StreamingMovies]) -> 0.38790288 | F18: One year | G18: No internet service | H18: No internet service | I18: =IF(Telco[[#This Row],[Churn]]="Yes",1,0) -> 0 | J18: Mailed check | K18: 8191-XWSZG
A19: % avec PhoneService : | C19: =COUNTIF(Telco[PhoneService],"Yes")/COUNTA(Telco[PhoneService]) -> 0.90316626 | F19: Two year | G19: Yes | H19: No | I19: =IF(Telco[[#This Row],[Churn]]="Yes",1,0) -> 0 | J19: Bank transfer (automatic) | K19: 9959-WOFKT
A20: % avec MultipleLines | C20: =COUNTIF(Telco[MultipleLines],"Yes")/COUNTA(Telco[MultipleLines]) -> 0.42183729 | F20: Month-to-month | G20: No | H20: Yes | I20: =IF(Telco[[#This Row],[Churn]]="Yes",1,0) -> 1 | J20: Credit card (automatic) | K20: 4190-MFLUW
A21: Moyenne charges mensuelles : | B21: =AVERAGE(Telco[MonthlyCharges]) -> 64.761692 | F21: Month-to-month | G21: No | H21: No | I21: =IF(Telco[[#This Row],[Churn]]="Yes",1,0) -> 0 | J21: Electronic check | K21: 4183-MYFRB | N21: Répartition du taux de désabonnement par méthode de paiement
A22: Charges totales trimestrielles (moyenne sur 3 mois) : | B22: =AVERAGE(Telco[MonthlyCharges])*3 -> 194.28508 | F22: Month-to-month | G22: No | H22: No | I22: =IF(Telco[[#This Row],[Churn]]="Yes",1,0) -> 1 | J22: Electronic check | K22: 8779-QRDMV
F23: One year | G23: No internet service | H23: No internet service | I23: =IF(Telco[[#This Row],[Churn]]="Yes",1,0) -> 0 | J23: Bank transfer (automatic) | K23: 1680-VDCWW | N23: Étiquettes de lignes | O23: Moyenne de ChurnFlag
F24: Month-to-month | G24: No internet service | H24: No internet service | I24: =IF(Telco[[#This Row],[Churn]]="Yes",1,0) -> 1 | J24: Mailed check | K24: 1066-JKSGK | N24: Bank transfer (automatic) | O24: 0.16709845
A25: % churn clients âgés | C25: =AVERAGEIF(Telco[SeniorCitizen],1,Telco[ChurnFlag]) -> 0.41681261 | F25: Two year | G25: No | H25: Yes | I25: =IF(Telco[[#This Row],[Churn]]="Yes",1,0) -> 0 | J25: Credit card (automatic) | K25: 3638-WEABW | N25: Credit card (automatic) | O25: 0.15243101
A26: % churn clients non âgés : | C26: =AVERAGEIF(Telco[SeniorCitizen],0,Telco[ChurnFlag]) -> 0.23606168 | F26: Month-to-month | G26: Yes | H26: Yes | I26: =IF(Telco[[#This Row],[Churn]]="Yes",1,0) -> 0 | J26: Credit card (automatic) | K26: 6322-HRPFA | N26: Electronic check | O26: 0.45285412
F27: Month-to-month | G27: Yes | H27: No | I27: =IF(Telco[[#This Row],[Churn]]="Yes",1,0) -> 0 | J27: Bank transfer (automatic) | K27: 6865-JZNKO | N27: Mailed check | O27: 0.191067
F28: Month-to-month | G28: No | H28: No | I28: =IF(Telco[[#This Row],[Churn]]="Yes",1,0) -> 1 | J28: Electronic check | K28: 6467-CHFZW | N28: (vide)
F29: Month-to-month | G29: No | H29: No | I29: =IF(Telco[[#This Row],[Churn]]="Yes",1,0) -> 1 | J29: Electronic check | K29: 8665-UTDHZ | N29: Total général | O29: 0.26536987
F30: Two year | G30: Yes | H30: Yes | I30: =IF(Telco[[#This Row],[Churn]]="Yes",1,0) -> 0 | J30: Credit card (automatic) | K30: 5248-YGIJN
F31: Month-to-month | G31: No | H31: No | I31: =IF(Telco[[#This Row],[Churn]]="Yes",1,0) -> 1 | J31: Mailed check | K31: 8773-HHUOZ
F32: Two year | G32: Yes | H32: Yes | I32: =IF(Telco[[#This Row],[Churn]]="Yes",1,0) -> 0 | J32: Credit card (automatic) | K32: 3841-NFECX
F33: Month-to-month | G33: No | H33: No | I33: =IF(Telco[[#This Row],[Churn]]="Yes",1,0) -> 0 | J33: Credit card (automatic) | K33: 4929-XIHVW
F34: One year | G34: Yes | H34: Yes | I34: =IF(Telco[[#This Row],[Churn]]="Yes",1,0) -> 0 | J34: Mailed check | K34: 6827-IEAUQ | N34: Répartition du taux de désabonnement par durée du contrat
F35: Month-to-month | G35: No internet service | H35: No internet service | I35: =IF(Telco[[#This Row],[Churn]]="Yes",1,0) -> 0 | J35: Bank transfer (automatic) | K35: 7310-EGVHZ
F36: Month-to-month | G36: No | H36: No | I36: =IF(Telco[[#This Row],[Churn]]="Yes",1,0) -> 0 | J36: Bank transfer (automatic) | K36: 3413-BMNZE | N36: Étiquettes de lignes | O36: Moyenne de ChurnFlag
F37: Two year | G37: Yes | H37: Yes | I37: =IF(Telco[[#This Row],[Churn]]="Yes",1,0) -> 0 | J37: Bank transfer (automatic) | K37: 6234-RAAPL | N37: Month-to-month | O37: 0.42709677
F38: Month-to-month | G38: No | H38: No | I38: =IF(Telco[[#This Row],[Churn]]="Yes",1,0) -> 1 | J38: Electronic check | K38: 6047-YHPVI | N38: One year | O38: 0.11269518
F39: Month-to-month | G39: No | H39: No | I39: =IF(Telco[[#This Row],[Churn]]="Yes",1,0) -> 0 | J39: Credit card (automatic) | K39: 6572-ADKRS | N39: Two year | O39: 0.028318584
F40: Month-to-month | G40: No | H40: No | I40: =IF(Telco[[#This Row],[Churn]]="Yes",1,0) -> 1 | J40: Electronic check | K40: 5380-WJKOV | N40: (vide)
...

Sheet Dashboard
A1: Taux de churn (%) | C1: Clients masculins/féminins (%) | E1: % de clients agés | F1: % de clients non agés | G1: Montant mensuel moyen
A3: ='feuille KPI'!$B$2 -> 0.26536987 | C3: ='feuille KPI'!$C$4 -> 0.5047565 | D3: ='feuille KPI'!$C$5 -> 0.4952435 | E3: ='feuille KPI'!$C$8 -> 0.16214681 | F3: ='feuille KPI'!$C$9 -> 0.83785319 | G3: ='feuille KPI'!$B$21 -> 64.761692
